Workbook

Sheet Panduan
A1: Buku Kas Publik — PT Daya Reforestasi Indonesia
A2: Template pencatatan keuangan & dampak terbuka. Baca panduan ini sebelum mulai mengisi.
B4: Cara mengisi
B5: 1. Hapus semua baris [CONTOH] di tab Transaksi dan Dampak sebelum mulai mencatat (pilih baris → hapus isi sel putihnya saja).
B6: 2. Tab Transaksi: satu baris untuk setiap uang masuk atau keluar. Pilih Jenis, Kategori, dan Proyek dari dropdown.
B7: 3. Isi Jumlah sebagai angka positif tanpa titik atau 'Rp'. Arah uang ditentukan oleh kolom Jenis (Masuk/Keluar).
B8: 4. Unggah foto nota/kuitansi ke folder Google Drive bersama, lalu tempel tautannya di kolom Tautan Bukti.
B9: 5. Status 'Menunggu Verifikasi' sampai orang kedua (bukan pencatat) mencocokkan bukti dan jumlah, lalu ubah ke 'Terverifikasi'.
B10: 6. Tab Dampak: catat capaian BARU saja per baris (mis. 200 pohon ditanam minggu ini), bukan total kumulatif.
B11: 7. Tab Ringkasan terisi otomatis. Ganti sel kuning 'Tahun' untuk melihat arus kas bulanan tahun lain.
B12: 8. Perlu kategori, proyek, atau indikator baru? Tambahkan di baris kuning tab Referensi; dropdown ikut bertambah.
B14: Arti warna
B15: Sel putih = diisi manual · Sel abu-abu = otomatis (rumus), jangan diubah · Sel kuning = boleh diubah/ditambah
B16: Kolom 'Cek' berwarna merah artinya Jenis tidak cocok dengan Kategori (mis. 'Penjualan Bibit' dicatat sebagai Keluar).
... B34: Ringkasan di file ini berbasis kas (uang masuk dan keluar). Ini bukan pengganti laporan keuangan resmi PT. Untuk laporan keuangan dan perpajakan, konsultasikan dengan akuntan atau konsultan pajak.

Sheet Ringkasan
A1: Ringkasan Keuangan & Dampak
A2: Seluruh tab ini terisi otomatis dari tab Transaksi dan Dampak. Hanya sel kuning (Tahun) yang boleh diubah.
A4: A. Posisi Keseluruhan (sejak awal pencatatan) | D4: E. Dampak (sejak awal pencatatan)
A5: Pendapatan usaha | B5: =SUMIFS(Transaksi!$J$5:$J$1004,Transaksi!$F$5:$F$1004,"Pendapatan Usaha",Transaksi!$M$5:$M$1004,"Terverifikasi",Transaksi!$H$5:$H$1004,"<>*[CONTOH]*") | D5: Indikator | E5: Satuan | F5: Total | G5: Terverifikasi
A6: Pendanaan & modal | B6: =SUMIFS(Transaksi!$J$5:$J$1004,Transaksi!$F$5:$F$1004,"Pendanaan & Modal",Transaksi!$M$5:$M$1004,"Terverifikasi",Transaksi!$H$5:$H$1004,"<>*[CONTOH]*") | D6: =IF(Referensi!$I$5="","",Referensi!$I$5) | E6: =IF(D6="","",Referensi!$J$5) | F6: =IF(D6="","",SUMIFS(Dampak!$E$5:$E$1004,Dampak!$D$5:$D$1004,D6,Dampak!$H$5:$H$1004,"<>*[CONTOH]*")) | G6: =IF(D6="","",SUMIFS(Dampak!$E$5:$E$1004,Dampak!$D$5:$D$1004,D6,Dampak!$J$5:$J$1004,"Terverifikasi",Dampak!$H$5:$H$1004,"<>*[CONTOH]*"))
A7: Total uang masuk | B7: =B5+B6 | D7: =IF(Referensi!$I$6="","",Referensi!$I$6) | E7: =IF(D7="","",Referensi!$J$6) | F7: =IF(D7="","",SUMIFS(Dampak!$E$5:$E$1004,Dampak!$D$5:$D$1004,D7,Dampak!$H$5:$H$1004,"<>*[CONTOH]*")) | G7: =IF(D7="","",SUMIFS(Dampak!$E$5:$E$1004,Dampak!$D$5:$D$1004,D7,Dampak!$J$5:$J$1004,"Terverifikasi",Dampak!$H$5:$H$1004,"<>*[CONTOH]*"))
A8: Biaya proyek (langsung ke lapangan) | B8: =SUMIFS(Transaksi!$J$5:$J$1004,Transaksi!$F$5:$F$1004,"Biaya Proyek",Transaksi!$M$5:$M$1004,"Terverifikasi",Transaksi!$H$5:$H$1004,"<>*[CONTOH]*") | D8: =IF(Referensi!$I$7="","",Referensi!$I$7) | E8: =IF(D8="","",Referensi!$J$7) | F8: =IF(D8="","",SUMIFS(Dampak!$E$5:$E$1004,Dampak!$D$5:$D$1004,D8,Dampak!$H$5:$H$1004,"<>*[CONTOH]*")) | G8: =IF(D8="","",SUMIFS(Dampak!$E$5:$E$1004,Dampak!$D$5:$D$1004,D8,Dampak!$J$5:$J$1004,"Terverifikasi",Dampak!$H$5:$H$1004,"<>*[CONTOH]*"))
A9: Biaya operasional | B9: =SUMIFS(Transaksi!$J$5:$J$1004,Transaksi!$F$5:$F$1004,"Biaya Operasional",Transaksi!$M$5:$M$1004,"Terverifikasi",Transaksi!$H$5:$H$1004,"<>*[CONTOH]*") | D9: =IF(Referensi!$I$8="","",Referensi!$I$8) | E9: =IF(D9="","",Referensi!$J$8) | F9: =IF(D9="","",SUMIFS(Dampak!$E$5:$E$1004,Dampak!$D$5:$D$1004,D9,Dampak!$H$5:$H$1004,"<>*[CONTOH]*")) | G9: =IF(D9="","",SUMIFS(Dampak!$E$5:$E$1004,Dampak!$D$5:$D$1004,D9,Dampak!$J$5:$J$1004,"Terverifikasi",Dampak!$H$5:$H$1004,"<>*[CONTOH]*"))
A10: Pajak | B10: =SUMIFS(Transaksi!$J$5:$J$1004,Transaksi!$F$5:$F$1004,"Pajak",Transaksi!$M$5:$M$1004,"Terverifikasi",Transaksi!$H$5:$H$1004,"<>*[CONTOH]*") | D10: =IF(Referensi!$I$9="","",Referensi!$I$9) | E10: =IF(D10="","",Referensi!$J$9) | F10: =IF(D10="","",SUMIFS(Dampak!$E$5:$E$1004,Dampak!$D$5:$D$1004,D10,Dampak!$H$5:$H$1004,"<>*[CONTOH]*")) | G10: =IF(D10="","",SUMIFS(Dampak!$E$5:$E$1004,Dampak!$D$5:$D$1004,D10,Dampak!$J$5:$J$1004,"Terverifikasi",Dampak!$H$5:$H$1004,"<>*[CONTOH]*"))
A11: Total uang keluar | B11: =B8+B9+B10 | D11: =IF(Referensi!$I$10="","",Referensi!$I$10) | E11: =IF(D11="","",Referensi!$J$10) | F11: =IF(D11="","",SUMIFS(Dampak!$E$5:$E$1004,Dampak!$D$5:$D$1004,D11,Dampak!$H$5:$H$1004,"<>*[CONTOH]*")) | G11: =IF(D11="","",SUMIFS(Dampak!$E$5:$E$1004,Dampak!$D$5:$D$1004,D11,Dampak!$J$5:$J$1004,"Terverifikasi",Dampak!$H$5:$H$1004,"<>*[CONTOH]*"))
A12: Saldo kas | B12: =B7-B11 | D12: =IF(Referensi!$I$11="","",Referensi!$I$11) | E12: =IF(D12="","",Referensi!$J$11) | F12: =IF(D12="","",SUMIFS(Dampak!$E$5:$E$1004,Dampak!$D$5:$D$1004,D12,Dampak!$H$5:$H$1004,"<>*[CONTOH]*")) | G12: =IF(D12="","",SUMIFS(Dampak!$E$5:$E$1004,Dampak!$D$5:$D$1004,D12,Dampak!$J$5:$J$1004,"Terverifikasi",Dampak!$H$5:$H$1004,"<>*[CONTOH]*"))
A13: Laba / (rugi) usaha | B13: =B5-B11 | D13: =IF(Referensi!$I$12="","",Referensi!$I$12) | E13: =IF(D13="","",Referensi!$J$12) | F13: =IF(D13="","",SUMIFS(Dampak!$E$5:$E$1004,Dampak!$D$5:$D$1004,D13,Dampak!$H$5:$H$1004,"<>*[CONTOH]*")) | G13: =IF(D13="","",SUMIFS(Dampak!$E$5:$E$1004,Dampak!$D$5:$D$1004,D13,Dampak!$J$5:$J$1004,"Terverifikasi",Dampak!$H$5:$H$1004,"<>*[CONTOH]*"))
A14: Porsi pengeluaran untuk proyek | B14: =IF(B11=0,0,B8/B11) | D14: =IF(Referensi!$I$13="","",Referensi!$I$13) | E14: =IF(D14="","",Referensi!$J$13) | F14: =IF(D14="","",SUMIFS(Dampak!$E$5:$E$1004,Dampak!$D$5:$D$1004,D14,Dampak!$H$5:$H$1004,"<>*[CONTOH]*")) | G14: =IF(D14="","",SUMIFS(Dampak!$E$5:$E$1004,Dampak!$D$5:$D$1004,D14,Dampak!$J$5:$J$1004,"Terverifikasi",Dampak!$H$5:$H$1004,"<>*[CONTOH]*"))
A15: Transaksi menunggu verifikasi | B15: =COUNTIFS(Transaksi!$M$5:$M$1004,"Menunggu Verifikasi",Transaksi!$H$5:$H$1004,"<>*[CONTOH]*") | D15: =IF(Referensi!$I$14="","",Referensi!$I$14) | E15: =IF(D15="","",Referensi!$J$14) | F15: =IF(D15="","",SUMIFS(Dampak!$E$5:$E$1004,Dampak!$D$5:$D$1004,D15,Dampak!$H$5:$H$1004,"<>*[CONTOH]*")) | G15: =IF(D15="","",SUMIFS(Dampak!$E$5:$E$1004,Dampak!$D$5:$D$1004,D15,Dampak!$J$5:$J$1004,"Terverifikasi",Dampak!$H$5:$H$1004,"<>*[CONTOH]*"))
A16: Catatan: ringkasan berbasis kas (uang masuk/keluar), bukan laporan keuangan resmi. Laba/(rugi) usaha = pendapatan usaha − seluruh pengeluaran; modal & investasi tidak dihitung sebagai pendapatan. Semua angka uang hanya menghitung transaksi berstatus Terverifikasi; baris [CONTOH] tidak pernah dihitung. | D16: 10 indikator pertama dari tab Referensi.
A17: Uang masuk yang belum dikelompokkan (kategori tidak dikenal): | B17: =SUMIFS(Transaksi!$J$5:$J$1004,Transaksi!$F$5:$F$1004,"?",Transaksi!$M$5:$M$1004,"Terverifikasi",Transaksi!$H$5:$H$1004,"<>*[CONTOH]*")
A19: B. Arus Kas Bulanan
A20: Tahun | B20: 2026
A21: Bulan | B21: Pendapatan Usaha | C21: Pendanaan & Modal | D21: Total Masuk | E21: Biaya Proyek | F21: Biaya Operasional | G21: Pajak | H21: Total Keluar | I21: Selisih Bulan Ini | J21: Saldo Akhir Bulan
A22: Januari | B22: =SUMIFS(Transaksi!$J$5:$J$1004,Transaksi!$F$5:$F$1004,"Pendapatan Usaha",Transaksi!$B$5:$B$1004,">="&DATE($B$20,1,1),Transaksi!$B$5:$B$1004,"<"&DATE($B$20,2,1),Transaksi!$M$5:$M$1004,"Terverifikasi",Transaksi!$H$5:$H$1004,"<>*[CONTOH]*") | C22: =SUMIFS(Transaksi!$J$5:$J$1004,Transaksi!$F$5:$F$1004,"Pendanaan & Modal",Transaksi!$B$5:$B$1004,">="&DATE($B$20,1,1),Transaksi!$B$5:$B$1004,"<"&DATE($B$20,2,1),Transaksi!$M$5:$M$1004,"Terverifikasi",Transaksi!$H$5:$H$1004,"<>*[CONTOH]*") | D22: =B22+C22 | E22: =SUMIFS(Transaksi!$J$5:$J$1004,Transaksi!$F$5:$F$1004,"Biaya Proyek",Transaksi!$B$5:$B$1004,">="&DATE($B$20,1,1),Transaksi!$B$5:$B$1004,"<"&DATE($B$20,2,1),Transaksi!$M$5:$M$1004,"Terverifikasi",Transaksi!$H$5:$H$1004,"<>*[CONTOH]*") | F22: =SUMIFS(Transaksi!$J$5:$J$1004,Transaksi!$F$5:$F$1004,"Biaya Operasional",Transaksi!$B$5:$B$1004,">="&DATE($B$20,1,1),Transaksi!$B$5:$B$1004,"<"&DATE($B$20,2,1),Transaksi!$M$5:$M$1004,"Terverifikasi",Transaksi!$H$5:$H$1004,"<>*[CONTOH]*") | G22: =SUMIFS(Transaksi!$J$5:$J$1004,Transaksi!$F$5:$F$1004,"Pajak",Transaksi!$B$5:$B$1004,">="&DATE($B$20,1,1),Transaksi!$B$5:$B$1004,"<"&DATE($B$20,2,1),Transaksi!$M$5:$M$1004,"Terverifikasi",Transaksi!$H$5:$H$1004,"<>*[CONTOH]*") | H22: =E22+F22+G22 | I22: =D22-H22 | J22: =SUMIFS(Transaksi!$J$5:$J$1004,Transaksi!$D$5:$D$1004,"Masuk",Transaksi!$B$5:$B$1004,"<"&DATE($B$20,2,1),Transaksi!$M$5:$M$1004,"Terverifikasi",Transaksi!$H$5:$H$1004,"<>*[CONTOH]*")-SUMIFS(Transaksi!$J$5:$J$1004,Transaksi!$D$5:$D$1004,"Keluar",Transaksi!$B$5:$B$1004,"<"&DATE($B$20,2,1),Transaksi!$M$5:$M$1004,"Terverifikasi",Transaksi!$H$5:$H$1004,"<>*[CONTOH]*")
A23: Februari | B23: =SUMIFS(Transaksi!$J$5:$J$1004,Transaksi!$F$5:$F$1004,"Pendapatan Usaha",Transaksi!$B$5:$B$1004,">="&DATE($B$20,2,1),Transaksi!$B$5:$B$1004,"<"&DATE($B$20,3,1),Transaksi!$M$5:$M$1004,"Terverifikasi",Transaksi!$H$5:$H$1004,"<>*[CONTOH]*") | C23: =SUMIFS(Transaksi!$J$5:$J$1004,Transaksi!$F$5:$F$1004,"Pendanaan & Modal",Transaksi!$B$5:$B$1004,">="&DATE($B$20,2,1),Transaksi!$B$5:$B$1004,"<"&DATE($B$20,3,1),Transaksi!$M$5:$M$1004,"Terverifikasi",Transaksi!$H$5:$H$1004,"<>*[CONTOH]*") | D23: =B23+C23 | E23: =SUMIFS(Transaksi!$J$5:$J$1004,Transaksi!$F$5:$F$1004,"Biaya Proyek",Transaksi!$B$5:$B$1004,">="&DATE($B$20,2,1),Transaksi!$B$5:$B$1004,"<"&DATE($B$20,3,1),Transaksi!$M$5:$M$1004,"Terverifikasi",Transaksi!$H$5:$H$1004,"<>*[CONTOH]*") | F23: =SUMIFS(Transaksi!$J$5:$J$1004,Transaksi!$F$5:$F$1004,"Biaya Operasional",Transaksi!$B$5:$B$1004,">="&DATE($B$20,2,1),Transaksi!$B$5:$B$1004,"<"&DATE($B$20,3,1),Transaksi!$M$5:$M$1004,"Terverifikasi",Transaksi!$H$5:$H$1004,"<>*[CONTOH]*") | G23: =SUMIFS(Transaksi!$J$5:$J$1004,Transaksi!$F$5:$F$1004,"Pajak",Transaksi!$B$5:$B$1004,">="&DATE($B$20,2,1),Transaksi!$B$5:$B$1004,"<"&DATE($B$20,3,1),Transaksi!$M$5:$M$1004,"Terverifikasi",Transaksi!$H$5:$H$1004,"<>*[CONTOH]*") | H23: =E23+F23+G23 | I23: =D23-H23 | J23: =SUMIFS(Transaksi!$J$5:$J$1004,Transaksi!$D$5:$D$1004,"Masuk",Transaksi!$B$5:$B$1004,"<"&DATE($B$20,3,1),Transaksi!$M$5:$M$1004,"Terverifikasi",Transaksi!$H$5:$H$1004,"<>*[CONTOH]*")-SUMIFS(Transaksi!$J$5:$J$1004,Transaksi!$D$5:$D$1004,"Keluar",Transaksi!$B$5:$B$1004,"<"&DATE($B$20,3,1),Transaksi!$M$5:$M$1004,"Terverifikasi",Transaksi!$H$5:$H$1004,"<>*[CONTOH]*")
A24: Maret | B24: =SUMIFS(Transaksi!$J$5:$J$1004,Transaksi!$F$5:$F$1004,"Pendapatan Usaha",Transaksi!$B$5:$B$1004,">="&DATE($B$20,3,1),Transaksi!$B$5:$B$1004,"<"&DATE($B$20,4,1),Transaksi!$M$5:$M$1004,"Terverifikasi",Transaksi!$H$5:$H$1004,"<>*[CONTOH]*") | C24: =SUMIFS(Transaksi!$J$5:$J$1004,Transaksi!$F$5:$F$1004,"Pendanaan & Modal",Transaksi!$B$5:$B$1004,">="&DATE($B$20,3,1),Transaksi!$B$5:$B$1004,"<"&DATE($B$20,4,1),Transaksi!$M$5:$M$1004,"Terverifikasi",Transaksi!$H$5:$H$1004,"<>*[CONTOH]*") | D24: =B24+C24 | E24: =SUMIFS(Transaksi!$J$5:$J$1004,Transaksi!$F$5:$F$1004,"Biaya Proyek",Transaksi!$B$5:$B$1004,">="&DATE($B$20,3,1),Transaksi!$B$5:$B$1004,"<"&DATE($B$20,4,1),Transaksi!$M$5:$M$1004,"Terverifikasi",Transaksi!$H$5:$H$1004,"<>*[CONTOH]*") | F24: =SUMIFS(Transaksi!$J$5:$J$1004,Transaksi!$F$5:$F$1004,"Biaya Operasional",Transaksi!$B$5:$B$1004,">="&DATE($B$20,3,1),Transaksi!$B$5:$B$1004,"<"&DATE($B$20,4,1),Transaksi!$M$5:$M$1004,"Terverifikasi",Transaksi!$H$5:$H$1004,"<>*[CONTOH]*") | G24: =SUMIFS(Transaksi!$J$5:$J$1004,Transaksi!$F$5:$F$1004,"Pajak",Transaksi!$B$5:$B$1004,">="&DATE($B$20,3,1),Transaksi!$B$5:$B$1004,"<"&DATE($B$20,4,1),Transaksi!$M$5:$M$1004,"Terverifikasi",Transaksi!$H$5:$H$1004,"<>*[CONTOH]*") | H24: =E24+F24+G24 | I24: =D24-H24 | J24: =SUMIFS(Transaksi!$J$5:$J$1004,Transaksi!$D$5:$D$1004,"Masuk",Transaksi!$B$5:$B$1004,"<"&DATE($B$20,4,1),Transaksi!$M$5:$M$1004,"Terverifikasi",Transaksi!$H$5:$H$1004,"<>*[CONTOH]*")-SUMIFS(Transaksi!$J$5:$J$1004,Transaksi!$D$5:$D$1004,"Keluar",Transaksi!$B$5:$B$1004,"<"&DATE($B$20,4,1),Transaksi!$M$5:$M$1004,"Terverifikasi",Transaksi!$H$5:$H$1004,"<>*[CONTOH]*")
A25: April | B25: =SUMIFS(Transaksi!$J$5:$J$1004,Transaksi!$F$5:$F$1004,"Pendapatan Usaha",Transaksi!$B$5:$B$1004,">="&DATE($B$20,4,1),Transaksi!$B$5:$B$1004,"<"&DATE($B$20,5,1),Transaksi!$M$5:$M$1004,"Terverifikasi",Transaksi!$H$5:$H$1004,"<>*[CONTOH]*") | C25: =SUMIFS(Transaksi!$J$5:$J$1004,Transaksi!$F$5:$F$1004,"Pendanaan & Modal",Transaksi!$B$5:$B$1004,">="&DATE($B$20,4,1),Transaksi!$B$5:$B$1004,"<"&DATE($B$20,5,1),Transaksi!$M$5:$M$1004,"Terverifikasi",Transaksi!$H$5:$H$1004,"<>*[CONTOH]*") | D25: =B25+C25 | E25: =SUMIFS(Transaksi!$J$5:$J$1004,Transaksi!$F$5:$F$1004,"Biaya Proyek",Transaksi!$B$5:$B$1004,">="&DATE($B$20,4,1),Transaksi!$B$5:$B$1004,"<"&DATE($B$20,5,1),Transaksi!$M$5:$M$1004,"Terverifikasi",Transaksi!$H$5:$H$1004,"<>*[CONTOH]*") | F25: =SUMIFS(Transaksi!$J$5:$J$1004,Transaksi!$F$5:$F$1004,"Biaya Operasional",Transaksi!$B$5:$B$1004,">="&DATE($B$20,4,1),Transaksi!$B$5:$B$1004,"<"&DATE($B$20,5,1),Transaksi!$M$5:$M$1004,"Terverifikasi",Transaksi!$H$5:$H$1004,"<>*[CONTOH]*") | G25: =SUMIFS(Transaksi!$J$5:$J$1004,Transaksi!$F$5:$F$1004,"Pajak",Transaksi!$B$5:$B$1004,">="&DATE($B$20,4,1),Transaksi!$B$5:$B$1004,"<"&DATE($B$20,5,1),Transaksi!$M$5:$M$1004,"Terverifikasi",Transaksi!$H$5:$H$1004,"<>*[CONTOH]*") | H25: =E25+F25+G25 | I25: =D25-H25 | J25: =SUMIFS(Transaksi!$J$5:$J$1004,Transaksi!$D$5:$D$1004,"Masuk",Transaksi!$B$5:$B$1004,"<"&DATE($B$20,5,1),Transaksi!$M$5:$M$1004,"Terverifikasi",Transaksi!$H$5:$H$1004,"<>*[CONTOH]*")-SUMIFS(Transaksi!$J$5:$J$1004,Transaksi!$D$5:$D$1004,"Keluar",Transaksi!$B$5:$B$1004,"<"&DATE($B$20,5,1),Transaksi!$M$5:$M$1004,"Terverifikasi",Transaksi!$H$5:$H$1004,"<>*[CONTOH]*")
A26: Mei | B26: =SUMIFS(Transaksi!$J$5:$J$1004,Transaksi!$F$5:$F$1004,"Pendapatan Usaha",Transaksi!$B$5:$B$1004,">="&DATE($B$20,5,1),Transaksi!$B$5:$B$1004,"<"&DATE($B$20,6,1),Transaksi!$M$5:$M$1004,"Terverifikasi",Transaksi!$H$5:$H$1004,"<>*[CONTOH]*") | C26: =SUMIFS(Transaksi!$J$5:$J$1004,Transaksi!$F$5:$F$1004,"Pendanaan & Modal",Transaksi!$B$5:$B$1004,">="&DATE($B$20,5,1),Transaksi!$B$5:$B$1004,"<"&DATE($B$20,6,1),Transaksi!$M$5:$M$1004,"Terverifikasi",Transaksi!$H$5:$H$1004,"<>*[CONTOH]*") | D26: =B26+C26 | E26: =SUMIFS(Transaksi!$J$5:$J$1004,Transaksi!$F$5:$F$1004,"Biaya Proyek",Transaksi!$B$5:$B$1004,">="&DATE($B$20,5,1),Transaksi!$B$5:$B$1004,"<"&DATE($B$20,6,1),Transaksi!$M$5:$M$1004,"Terverifikasi",Transaksi!$H$5:$H$1004,"<>*[CONTOH]*") | F26: =SUMIFS(Transaksi!$J$5:$J$1004,Transaksi!$F$5:$F$1004,"Biaya Operasional",Transaksi!$B$5:$B$1004,">="&DATE($B$20,5,1),Transaksi!$B$5:$B$1004,"<"&DATE($B$20,6,1),Transaksi!$M$5:$M$1004,"Terverifikasi",Transaksi!$H$5:$H$1004,"<>*[CONTOH]*") | G26: =SUMIFS(Transaksi!$J$5:$J$1004,Transaksi!$F$5:$F$1004,"Pajak",Transaksi!$B$5:$B$1004,">="&DATE($B$20,5,1),Transaksi!$B$5:$B$1004,"<"&DATE($B$20,6,1),Transaksi!$M$5:$M$1004,"Terverifikasi",Transaksi!$H$5:$H$1004,"<>*[CONTOH]*") | H26: =E26+F26+G26 | I26: =D26-H26 | J26: =SUMIFS(Transaksi!$J$5:$J$1004,Transaksi!$D$5:$D$1004,"Masuk",Transaksi!$B$5:$B$1004,"<"&DATE($B$20,6,1),Transaksi!$M$5:$M$1004,"Terverifikasi",Transaksi!$H$5:$H$1004,"<>*[CONTOH]*")-SUMIFS(Transaksi!$J$5:$J$1004,Transaksi!$D$5:$D$1004,"Keluar",Transaksi!$B$5:$B$1004,"<"&DATE($B$20,6,1),Transaksi!$M$5:$M$1004,"Terverifikasi",Transaksi!$H$5:$H$1004,"<>*[CONTOH]*")
A27: Juni | B27: =SUMIFS(Transaksi!$J$5:$J$1004,Transaksi!$F$5:$F$1004,"Pendapatan Usaha",Transaksi!$B$5:$B$1004,">="&DATE($B$20,6,1),Transaksi!$B$5:$B$1004,"<"&DATE($B$20,7,1),Transaksi!$M$5:$M$1004,"Terverifikasi",Transaksi!$H$5:$H$1004,"<>*[CONTOH]*") | C27: =SUMIFS(Transaksi!$J$5:$J$1004,Transaksi!$F$5:$F$1004,"Pendanaan & Modal",Transaksi!$B$5:$B$1004,">="&DATE($B$20,6,1),Transaksi!$B$5:$B$1004,"<"&DATE($B$20,7,1),Transaksi!$M$5:$M$1004,"Terverifikasi",Transaksi!$H$5:$H$1004,"<>*[CONTOH]*") | D27: =B27+C27 | E27: =SUMIFS(Transaksi!$J$5:$J$1004,Transaksi!$F$5:$F$1004,"Biaya Proyek",Transaksi!$B$5:$B$1004,">="&DATE($B$20,6,1),Transaksi!$B$5:$B$1004,"<"&DATE($B$20,7,1),Transaksi!$M$5:$M$1004,"Terverifikasi",Transaksi!$H$5:$H$1004,"<>*[CONTOH]*") | F27: =SUMIFS(Transaksi!$J$5:$J$1004,Transaksi!$F$5:$F$1004,"Biaya Operasional",Transaksi!$B$5:$B$1004,">="&DATE($B$20,6,1),Transaksi!$B$5:$B$1004,"<"&DATE($B$20,7,1),Transaksi!$M$5:$M$1004,"Terverifikasi",Transaksi!$H$5:$H$1004,"<>*[CONTOH]*") | G27: =SUMIFS(Transaksi!$J$5:$J$1004,Transaksi!$F$5:$F$1004,"Pajak",Transaksi!$B$5:$B$1004,">="&DATE($B$20,6,1),Transaksi!$B$5:$B$1004,"<"&DATE($B$20,7,1),Transaksi!$M$5:$M$1004,"Terverifikasi",Transaksi!$H$5:$H$1004,"<>*[CONTOH]*") | H27: =E27+F27+G27 | I27: =D27-H27 | J27: =SUMIFS(Transaksi!$J$5:$J$1004,Transaksi!$D$5:$D$1004,"Masuk",Transaksi!$B$5:$B$1004,"<"&DATE($B$20,7,1),Transaksi!$M$5:$M$1004,"Terverifikasi",Transaksi!$H$5:$H$1004,"<>*[CONTOH]*")-SUMIFS(Transaksi!$J$5:$J$1004,Transaksi!$D$5:$D$1004,"Keluar",Transaksi!$B$5:$B$1004,"<"&DATE($B$20,7,1),Transaksi!$M$5:$M$1004,"Terverifikasi",Transaksi!$H$5:$H$1004,"<>*[CONTOH]*")
A28: Juli | B28: =SUMIFS(Transaksi!$J$5:$J$1004,Transaksi!$F$5:$F$1004,"Pendapatan Usaha",Transaksi!$B$5:$B$1004,">="&DATE($B$20,7,1),Transaksi!$B$5:$B$1004,"<"&DATE($B$20,8,1),Transaksi!$M$5:$M$1004,"Terverifikasi",Transaksi!$H$5:$H$1004,"<>*[CONTOH]*") | C28: =SUMIFS(Transaksi!$J$5:$J$1004,Transaksi!$F$5:$F$1004,"Pendanaan & Modal",Transaksi!$B$5:$B$1004,">="&DATE($B$20,7,1),Transaksi!$B$5:$B$1004,"<"&DATE($B$20,8,1),Transaksi!$M$5:$M$1004,"Terverifikasi",Transaksi!$H$5:$H$1004,"<>*[CONTOH]*") | D28: =B28+C28 | E28: =SUMIFS(Transaksi!$J$5:$J$1004,Transaksi!$F$5:$F$1004,"Biaya Proyek",Transaksi!$B$5:$B$1004,">="&DATE($B$20,7,1),Transaksi!$B$5:$B$1004,"<"&DATE($B$20,8,1),Transaksi!$M$5:$M$1004,"Terverifikasi",Transaksi!$H$5:$H$1004,"<>*[CONTOH]*") | F28: =SUMIFS(Transaksi!$J$5:$J$1004,Transaksi!$F$5:$F$1004,"Biaya Operasional",Transaksi!$B$5:$B$1004,">="&DATE($B$20,7,1),Transaksi!$B$5:$B$1004,"<"&DATE($B$20,8,1),Transaksi!$M$5:$M$1004,"Terverifikasi",Transaksi!$H$5:$H$1004,"<>*[CONTOH]*") | G28: =SUMIFS(Transaksi!$J$5:$J$1004,Transaksi!$F$5:$F$1004,"Pajak",Transaksi!$B$5:$B$1004,">="&DATE($B$20,7,1),Transaksi!$B$5:$B$1004,"<"&DATE($B$20,8,1),Transaksi!$M$5:$M$1004,"Terverifikasi",Transaksi!$H$5:$H$1004,"<>*[CONTOH]*") | H28: =E28+F28+G28 | I28: =D28-H28 | J28: =SUMIFS(Transaksi!$J$5:$J$1004,Transaksi!$D$5:$D$1004,"Masuk",Transaksi!$B$5:$B$1004,"<"&DATE($B$20,8,1),Transaksi!$M$5:$M$1004,"Terverifikasi",Transaksi!$H$5:$H$1004,"<>*[CONTOH]*")-SUMIFS(Transaksi!$J$5:$J$1004,Transaksi!$D$5:$D$1004,"Keluar",Transaksi!$B$5:$B$1004,"<"&DATE($B$20,8,1),Transaksi!$M$5:$M$1004,"Terverifikasi",Transaksi!$H$5:$H$1004,"<>*[CONTOH]*")
A29: Agustus | B29: =SUMIFS(Transaksi!$J$5:$J$1004,Transaksi!$F$5:$F$1004,"Pendapatan Usaha",Transaksi!$B$5:$B$1004,">="&DATE($B$20,8,1),Transaksi!$B$5:$B$1004,"<"&DATE($B$20,9,1),Transaksi!$M$5:$M$1004,"Terverifikasi",Transaksi!$H$5:$H$1004,"<>*[CONTOH]*") | C29: =SUMIFS(Transaksi!$J$5:$J$1004,Transaksi!$F$5:$F$1004,"Pendanaan & Modal",Transaksi!$B$5:$B$1004,">="&DATE($B$20,8,1),Transaksi!$B$5:$B$1004,"<"&DATE($B$20,9,1),Transaksi!$M$5:$M$1004,"Terverifikasi",Transaksi!$H$5:$H$1004,"<>*[CONTOH]*") | D29: =B29+C29 | E29: =SUMIFS(Transaksi!$J$5:$J$1004,Transaksi!$F$5:$F$1004,"Biaya Proyek",Transaksi!$B$5:$B$1004,">="&DATE($B$20,8,1),Transaksi!$B$5:$B$1004,"<"&DATE($B$20,9,1),Transaksi!$M$5:$M$1004,"Terverifikasi",Transaksi!$H$5:$H$1004,"<>*[CONTOH]*") | F29: =SUMIFS(Transaksi!$J$5:$J$1004,Transaksi!$F$5:$F$1004,"Biaya Operasional",Transaksi!$B$5:$B$1004,">="&DATE($B$20,8,1),Transaksi!$B$5:$B$1004,"<"&DATE($B$20,9,1),Transaksi!$M$5:$M$1004,"Terverifikasi",Transaksi!$H$5:$H$1004,"<>*[CONTOH]*") | G29: =SUMIFS(Transaksi!$J$5:$J$1004,Transaksi!$F$5:$F$1004,"Pajak",Transaksi!$B$5:$B$1004,">="&DATE($B$20,8,1),Transaksi!$B$5:$B$1004,"<"&DATE($B$20,9,1),Transaksi!$M$5:$M$1004,"Terverifikasi",Transaksi!$H$5:$H$1004,"<>*[CONTOH]*") | H29: =E29+F29+G29 | I29: =D29-H29 | J29: =SUMIFS(Transaksi!$J$5:$J$1004,Transaksi!$D$5:$D$1004,"Masuk",Transaksi!$B$5:$B$1004,"<"&DATE($B$20,9,1),Transaksi!$M$5:$M$1004,"Terverifikasi",Transaksi!$H$5:$H$1004,"<>*[CONTOH]*")-SUMIFS(Transaksi!$J$5:$J$1004,Transaksi!$D$5:$D$1004,"Keluar",Transaksi!$B$5:$B$1004,"<"&DATE($B$20,9,1),Transaksi!$M$5:$M$1004,"Terverifikasi",Transaksi!$H$5:$H$1004,"<>*[CONTOH]*")
A30: September | B30: =SUMIFS(Transaksi!$J$5:$J$1004,Transaksi!$F$5:$F$1004,"Pendapatan Usaha",Transaksi!$B$5:$B$1004,">="&DATE($B$20,9,1),Transaksi!$B$5:$B$1004,"<"&DATE($B$20,10,1),Transaksi!$M$5:$M$1004,"Terverifikasi",Transaksi!$H$5:$H$1004,"<>*[CONTOH]*") | C30: =SUMIFS(Transaksi!$J$5:$J$1004,Transaksi!$F$5:$F$1004,"Pendanaan & Modal",Transaksi!$B$5:$B$1004,">="&DATE($B$20,9,1),Transaksi!$B$5:$B$1004,"<"&DATE($B$20,10,1),Transaksi!$M$5:$M$1004,"Terverifikasi",Transaksi!$H$5:$H$1004,"<>*[CONTOH]*") | D30: =B30+C30 | E30: =SUMIFS(Transaksi!$J$5:$J$1004,Transaksi!$F$5:$F$1004,"Biaya Proyek",Transaksi!$B$5:$B$1004,">="&DATE($B$20,9,1),Transaksi!$B$5:$B$1004,"<"&DATE($B$20,10,1),Transaksi!$M$5:$M$1004,"Terverifikasi",Transaksi!$H$5:$H$1004,"<>*[CONTOH]*") | F30: =SUMIFS(Transaksi!$J$5:$J$1004,Transaksi!$F$5:$F$1004,"Biaya Operasional",Transaksi!$B$5:$B$1004,">="&DATE($B$20,9,1),Transaksi!$B$5:$B$1004,"<"&DATE($B$20,10,1),Transaksi!$M$5:$M$1004,"Terverifikasi",Transaksi!$H$5:$H$1004,"<>*[CONTOH]*") | G30: =SUMIFS(Transaksi!$J$5:$J$1004,Transaksi!$F$5:$F$1004,"Pajak",Transaksi!$B$5:$B$1004,">="&DATE($B$20,9,1),Transaksi!$B$5:$B$1004,"<"&DATE($B$20,10,1),Transaksi!$M$5:$M$1004,"Terverifikasi",Transaksi!$H$5:$H$1004,"<>*[CONTOH]*") | H30: =E30+F30+G30 | I30: =D30-H30 | J30: =SUMIFS(Transaksi!$J$5:$J$1004,Transaksi!$D$5:$D$1004,"Masuk",Transaksi!$B$5:$B$1004,"<"&DATE($B$20,10,1),Transaksi!$M$5:$M$1004,"Terverifikasi",Transaksi!$H$5:$H$1004,"<>*[CONTOH]*")-SUMIFS(Transaksi!$J$5:$J$1004,Transaksi!$D$5:$D$1004,"Keluar",Transaksi!$B$5:$B$1004,"<"&DATE($B$20,10,1),Transaksi!$M$5:$M$1004,"Terverifikasi",Transaksi!$H$5:$H$1004,"<>*[CONTOH]*")
A31: Oktober | B31: =SUMIFS(Transaksi!$J$5:$J$1004,Transaksi!$F$5:$F$1004,"Pendapatan Usaha",Transaksi!$B$5:$B$1004,">="&DATE($B$20,10,1),Transaksi!$B$5:$B$1004,"<"&DATE($B$20,11,1),Transaksi!$M$5:$M$1004,"Terverifikasi",Transaksi!$H$5:$H$1004,"<>*[CONTOH]*") | C31: =SUMIFS(Transaksi!$J$5:$J$1004,Transaksi!$F$5:$F$1004,"Pendanaan & Modal",Transaksi!$B$5:$B$1004,">="&DATE($B$20,10,1),Transaksi!$B$5:$B$1004,"<"&DATE($B$20,11,1),Transaksi!$M$5:$M$1004,"Terverifikasi",Transaksi!$H$5:$H$1004,"<>*[CONTOH]*") | D31: =B31+C31 | E31: =SUMIFS(Transaksi!$J$5:$J$1004,Transaksi!$F$5:$F$1004,"Biaya Proyek",Transaksi!$B$5:$B$1004,">="&DATE($B$20,10,1),Transaksi!$B$5:$B$1004,"<"&DATE($B$20,11,1),Transaksi!$M$5:$M$1004,"Terverifikasi",Transaksi!$H$5:$H$1004,"<>*[CONTOH]*") | F31: =SUMIFS(Transaksi!$J$5:$J$1004,Transaksi!$F$5:$F$1004,"Biaya Operasional",Transaksi!$B$5:$B$1004,">="&DATE($B$20,10,1),Transaksi!$B$5:$B$1004,"<"&DATE($B$20,11,1),Transaksi!$M$5:$M$1004,"Terverifikasi",Transaksi!$H$5:$H$1004,"<>*[CONTOH]*") | G31: =SUMIFS(Transaksi!$J$5:$J$1004,Transaksi!$F$5:$F$1004,"Pajak",Transaksi!$B$5:$B$1004,">="&DATE($B$20,10,1),Transaksi!$B$5:$B$1004,"<"&DATE($B$20,11,1),Transaksi!$M$5:$M$1004,"Terverifikasi",Transaksi!$H$5:$H$1004,"<>*[CONTOH]*") | H31: =E31+F31+G31 | I31: =D31-H31 | J31: =SUMIFS(Transaksi!$J$5:$J$1004,Transaksi!$D$5:$D$1004,"Masuk",Transaksi!$B$5:$B$1004,"<"&DATE($B$20,11,1),Transaksi!$M$5:$M$1004,"Terverifikasi",Transaksi!$H$5:$H$1004,"<>*[CONTOH]*")-SUMIFS(Transaksi!$J$5:$J$1004,Transaksi!$D$5:$D$1004,"Keluar",Transaksi!$B$5:$B$1004,"<"&DATE($B$20,11,1),Transaksi!$M$5:$M$1004,"Terverifikasi",Transaksi!$H$5:$H$1004,"<>*[CONTOH]*")
A32: November | B32: =SUMIFS(Transaksi!$J$5:$J$1004,Transaksi!$F$5:$F$1004,"Pendapatan Usaha",Transaksi!$B$5:$B$1004,">="&DATE($B$20,11,1),Transaksi!$B$5:$B$1004,"<"&DATE($B$20,12,1),Transaksi!$M$5:$M$1004,"Terverifikasi",Transaksi!$H$5:$H$1004,"<>*[CONTOH]*") | C32: =SUMIFS(Transaksi!$J$5:$J$1004,Transaksi!$F$5:$F$1004,"Pendanaan & Modal",Transaksi!$B$5:$B$1004,">="&DATE($B$20,11,1),Transaksi!$B$5:$B$1004,"<"&DATE($B$20,12,1),Transaksi!$M$5:$M$1004,"Terverifikasi",Transaksi!$H$5:$H$1004,"<>*[CONTOH]*") | D32: =B32+C32 | E32: =SUMIFS(Transaksi!$J$5:$J$1004,Transaksi!$F$5:$F$1004,"Biaya Proyek",Transaksi!$B$5:$B$1004,">="&DATE($B$20,11,1),Transaksi!$B$5:$B$1004,"<"&DATE($B$20,12,1),Transaksi!$M$5:$M$1004,"Terverifikasi",Transaksi!$H$5:$H$1004,"<>*[CONTOH]*") | F32: =SUMIFS(Transaksi!$J$5:$J$1004,Transaksi!$F$5:$F$1004,"Biaya Operasional",Transaksi!$B$5:$B$1004,">="&DATE($B$20,11,1),Transaksi!$B$5:$B$1004,"<"&DATE($B$20,12,1),Transaksi!$M$5:$M$1004,"Terverifikasi",Transaksi!$H$5:$H$1004,"<>*[CONTOH]*") | G32: =SUMIFS(Transaksi!$J$5:$J$1004,Transaksi!$F$5:$F$1004,"Pajak",Transaksi!$B$5:$B$1004,">="&DATE($B$20,11,1),Transaksi!$B$5:$B$1004,"<"&DATE($B$20,12,1),Transaksi!$M$5:$M$1004,"Terverifikasi",Transaksi!$H$5:$H$1004,"<>*[CONTOH]*") | H32: =E32+F32+G32 | I32: =D32-H32 | J32: =SUMIFS(Transaksi!$J$5:$J$1004,Transaksi!$D$5:$D$1004,"Masuk",Transaksi!$B$5:$B$1004,"<"&DATE($B$20,12,1),Transaksi!$M$5:$M$1004,"Terverifikasi",Transaksi!$H$5:$H$1004,"<>*[CONTOH]*")-SUMIFS(Transaksi!$J$5:$J$1004,Transaksi!$D$5:$D$1004,"Keluar",Transaksi!$B$5:$B$1004,"<"&DATE($B$20,12,1),Transaksi!$M$5:$M$1004,"Terverifikasi",Transaksi!$H$5:$H$1004,"<>*[CONTOH]*")
A33: Desember | B33: =SUMIFS(Transaksi!$J$5:$J$1004,Transaksi!$F$5:$F$1004,"Pendapatan Usaha",Transaksi!$B$5:$B$1004,">="&DATE($B$20,12,1),Transaksi!$B$5:$B$1004,"<"&DATE($B$20+1,1,1),Transaksi!$M$5:$M$1004,"Terverifikasi",Transaksi!$H$5:$H$1004,"<>*[CONTOH]*") | C33: =SUMIFS(Transaksi!$J$5:$J$1004,Transaksi!$F$5:$F$1004,"Pendanaan & Modal",Transaksi!$B$5:$B$1004,">="&DATE($B$20,12,1),Transaksi!$B$5:$B$1004,"<"&DATE($B$20+1,1,1),Transaksi!$M$5:$M$1004,"Terverifikasi",Transaksi!$H$5:$H$1004,"<>*[CONTOH]*") | D33: =B33+C33 | E33: =SUMIFS(Transaksi!$J$5:$J$1004,Transaksi!$F$5:$F$1004,"Biaya Proyek",Transaksi!$B$5:$B$1004,">="&DATE($B$20,12,1),Transaksi!$B$5:$B$1004,"<"&DATE($B$20+1,1,1),Transaksi!$M$5:$M$1004,"Terverifikasi",Transaksi!$H$5:$H$1004,"<>*[CONTOH]*") | F33: =SUMIFS(Transaksi!$J$5:$J$1004,Transaksi!$F$5:$F$1004,"Biaya Operasional",Transaksi!$B$5:$B$1004,">="&DATE($B$20,12,1),Transaksi!$B$5:$B$1004,"<"&DATE($B$20+1,1,1),Transaksi!$M$5:$M$1004,"Terverifikasi",Transaksi!$H$5:$H$1004,"<>*[CONTOH]*") | G33: =SUMIFS(Transaksi!$J$5:$J$1004,Transaksi!$F$5:$F$1004,"Pajak",Transaksi!$B$5:$B$1004,">="&DATE($B$20,12,1),Transaksi!$B$5:$B$1004,"<"&DATE($B$20+1,1,1),Transaksi!$M$5:$M$1004,"Terverifikasi",Transaksi!$H$5:$H$1004,"<>*[CONTOH]*") | H33: =E33+F33+G33 | I33: =D33-H33 | J33: =SUMIFS(Transaksi!$J$5:$J$1004,Transaksi!$D$5:$D$1004,"Masuk",Transaksi!$B$5:$B$1004,"<"&DATE($B$20+1,1,1),Transaksi!$M$5:$M$1004,"Terverifikasi",Transaksi!$H$5:$H$1004,"<>*[CONTOH]*")-SUMIFS(Transaksi!$J$5:$J$1004,Transaksi!$D$5:$D$1004,"Keluar",Transaksi!$B$5:$B$1004,"<"&DATE($B$20+1,1,1),Transaksi!$M$5:$M$1004,"Terverifikasi",Transaksi!$H$5:$H$1004,"<>*[CONTOH]*")
A34: Total setahun | B34: =SUM(B22:B33) | C34: =SUM(C22:C33) | D34: =SUM(D22:D33) | E34: =SUM(E22:E33) | F34: =SUM(F22:F33) | G34: =SUM(G22:G33) | H34: =SUM(H22:H33) | I34: =SUM(I22:I33) | J34: =J33
A36: C. Per Proyek (sejak awal pencatatan)
A37: Proyek | B37: Uang Masuk | C37: Uang Keluar | D37: Selisih | E37: Porsi dari Total Keluar
A38: =IF(Referensi!$F$5="","",Referensi!$F$5) | B38: =IF(A38="","",SUMIFS(Transaksi!$J$5:$J$1004,Transaksi!$G$5:$G$1004,A38,Transaksi!$D$5:$D$1004,"Masuk",Transaksi!$M$5:$M$1004,"Terverifikasi",Transaksi!$H$5:$H$1004,"<>*[CONTOH]*")) | C38: =IF(A38="","",SUMIFS(Transaksi!$J$5:$J$1004,Transaksi!$G$5:$G$1004,A38,Transaksi!$D$5:$D$1004,"Keluar",Transaksi!$M$5:$M$1004,"Terverifikasi",Transaksi!$H$5:$H$1004,"<>*[CONTOH]*")) | D38: =IF(A38="","",B38-C38) | E38: =IF(A38="","",IF($B$11=0,0,C38/$B$11))
A39: =IF(Referensi!$F$6="","",Referensi!$F$6) | B39: =IF(A39="","",SUMIFS(Transaksi!$J$5:$J$1004,Transaksi!$G$5:$G$1004,A39,Transaksi!$D$5:$D$1004,"Masuk",Transaksi!$M$5:$M$1004,"Terverifikasi",Transaksi!$H$5:$H$1004,"<>*[CONTOH]*")) | C39: =IF(A39="","",SUMIFS(Transaksi!$J$5:$J$1004,Transaksi!$G$5:$G$1004,A39,Transaksi!$D$5:$D$1004,"Keluar",Transaksi!$M$5:$M$1004,"Terverifikasi",Transaksi!$H$5:$H$1004,"<>*[CONTOH]*")) | D39: =IF(A39="","",B39-C39) | E39: =IF(A39="","",IF($B$11=0,0,C39/$B$11))
A40: =IF(Referensi!$F$7="","",Referensi!$F$7) | B40: =IF(A40="","",SUMIFS(Transaksi!$J$5:$J$1004,Transaksi!$G$5:$G$1004,A40,Transaksi!$D$5:$D$1004,"Masuk",Transaksi!$M$5:$M$1004,"Terverifikasi",Transaksi!$H$5:$H$1004,"<>*[CONTOH]*")) | C40: =IF(A40="","",SUMIFS(Transaksi!$J$5:$J$1004,Transaksi!$G$5:$G$1004,A40,Transaksi!$D$5:$D$1004,"Keluar",Transaksi!$M$5:$M$1004,"Terverifikasi",Transaksi!$H$5:$H$1004,"<>*[CONTOH]*")) | D40: =IF(A40="","",B40-C40) | E40: =IF(A40="","",IF($B$11=0,0,C40/$B$11))
A41: =IF(Referensi!$F$8="","",Referensi!$F$8) | B41: =IF(A41="","",SUMIFS(Transaksi!$J$5:$J$1004,Transaksi!$G$5:$G$1004,A41,Transaksi!$D$5:$D$1004,"Masuk",Transaksi!$M$5:$M$1004,"Terverifikasi",Transaksi!$H$5:$H$1004,"<>*[CONTOH]*")) | C41: =IF(A41="","",SUMIFS(Transaksi!$J$5:$J$1004,Transaksi!$G$5:$G$1004,A41,Transaksi!$D$5:$D$1004,"Keluar",Transaksi!$M$5:$M$1004,"Terverifikasi",Transaksi!$H$5:$H$1004,"<>*[CONTOH]*")) | D41: =IF(A41="","",B41-C41) | E41: =IF(A41="","",IF($B$11=0,0,C41/$B$11))
A42: =IF(Referensi!$F$9="","",Referensi!$F$9) | B42: =IF(A42="","",SUMIFS(Transaksi!$J$5:$J$1004,Transaksi!$G$5:$G$1004,A42,Transaksi!$D$5:$D$1004,"Masuk",Transaksi!$M$5:$M$1004,"Terverifikasi",Transaksi!$H$5:$H$1004,"<>*[CONTOH]*")) | C42: =IF(A42="","",SUMIFS(Transaksi!$J$5:$J$1004,Transaksi!$G$5:$G$1004,A42,Transaksi!$D$5:$D$1004,"Keluar",Transaksi!$M$5:$M$1004,"Terverifikasi",Transaksi!$H$5:$H$1004,"<>*[CONTOH]*")) | D42: =IF(A42="","",B42-C42) | E42: =IF(A42="","",IF($B$11=0,0,C42/$B$11))
A43: =IF(Referensi!$F$10="","",Referensi!$F$10) | B43: =IF(A43="","",SUMIFS(Transaksi!$J$5:$J$1004,Transaksi!$G$5:$G$1004,A43,Transaksi!$D$5:$D$1004,"Masuk",Transaksi!$M$5:$M$1004,"Terverifikasi",Transaksi!$H$5:$H$1004,"<>*[CONTOH]*")) | C43: =IF(A43="","",SUMIFS(Transaksi!$J$5:$J$1004,Transaksi!$G$5:$G$1004,A43,Transaksi!$D$5:$D$1004,"Keluar",Transaksi!$M$5:$M$1004,"Terverifikasi",Transaksi!$H$5:$H$1004,"<>*[CONTOH]*")) | D43: =IF(A43="","",B43-C43) | E43: =IF(A43="","",IF($B$11=0,0,C43/$B$11))
...

Sheet Transaksi
A1: Buku Kas Publik — Transaksi
A2: Satu baris = satu transaksi. Isi kolom putih. Kolom abu-abu terisi otomatis, jangan diubah.
A4: No | B4: Tanggal | C4: No. Bukti | D4: Jenis | E4: Kategori | F4: Kelompok (otomatis) | G4: Proyek | H4: Keterangan | I4: Pihak Terkait | J4: Jumlah (Rp) | K4: Saldo Kas (otomatis) | L4: Tautan Bukti | M4: Status | N4: Cek (otomatis)
A5: =IF(B5="","",ROW()-4) | B5: 46296 | C5: BKM-2610-001 | D5: Masuk | E5: Modal Disetor Pemegang Saham | F5: =IF(E5="","",IFERROR(INDEX(Referensi!$C$5:$C$60,MATCH(E5,Referensi!$A$5:$A$60,0)),"?")) | G5: Umum Perusahaan | H5: [CONTOH] Setoran modal awal pendiri | I5: Pemegang saham PT | J5: 50000000 | K5: =IF(J5="","",SUMIFS(J$5:J5,D$5:D5,"Masuk")-SUMIFS(J$5:J5,D$5:D5,"Keluar")) | L5: https://drive.google.com/… (tautan foto nota) | M5: Terverifikasi | N5: =IF(E5="","",IFERROR(IF(INDEX(Referensi!$B$5:$B$60,MATCH(E5,Referensi!$A$5:$A$60,0))=D5,"OK","Jenis tidak cocok"),"Kategori tidak dikenal"))
A6: =IF(B6="","",ROW()-4) | B6: 46298 | C6: BKK-2610-001 | D6: Keluar | E6: Legal, Audit & Administrasi | F6: =IF(E6="","",IFERROR(INDEX(Referensi!$C$5:$C$60,MATCH(E6,Referensi!$A$5:$A$60,0)),"?")) | G6: Umum Perusahaan | H6: [CONTOH] Biaya notaris perubahan akta | I6: Kantor Notaris (badan usaha) | J6: 3500000 | K6: =IF(J6="","",SUMIFS(J$5:J6,D$5:D6,"Masuk")-SUMIFS(J$5:J6,D$5:D6,"Keluar")) | L6: https://drive.google.com/… (tautan foto nota) | M6: Terverifikasi | N6: =IF(E6="","",IFERROR(IF(INDEX(Referensi!$B$5:$B$60,MATCH(E6,Referensi!$A$5:$A$60,0))=D6,"OK","Jenis tidak cocok"),"Kategori tidak dikenal"))
A7: =IF(B7="","",ROW()-4) | B7: 46303 | C7: BKK-2610-002 | D7: Keluar | E7: Survei & Riset Lahan | F7: =IF(E7="","",IFERROR(INDEX(Referensi!$C$5:$C$60,MATCH(E7,Referensi!$A$5:$A$60,0)),"?")) | G7: Lapor Lahan & Riset | H7: [CONTOH] Survei lahan laporan warga #001 | I7: Tim survei (3 orang) | J7: 2750000 | K7: =IF(J7="","",SUMIFS(J$5:J7,D$5:D7,"Masuk")-SUMIFS(J$5:J7,D$5:D7,"Keluar")) | L7: https://drive.google.com/… (tautan foto nota) | M7: Terverifikasi | N7: =IF(E7="","",IFERROR(IF(INDEX(Referensi!$B$5:$B$60,MATCH(E7,Referensi!$A$5:$A$60,0))=D7,"OK","Jenis tidak cocok"),"Kategori tidak dikenal"))
A8: =IF(B8="","",ROW()-4) | B8: 46310 | C8: BKK-2610-003 | D8: Keluar | E8: Bibit & Material Tanam | F8: =IF(E8="","",IFERROR(INDEX(Referensi!$C$5:$C$60,MATCH(E8,Referensi!$A$5:$A$60,0)),"?")) | G8: Akar Bambu | H8: [CONTOH] 500 bibit bambu & 200 bibit katuk | I8: Persemaian mitra (badan usaha) | J8: 6250000 | K8: =IF(J8="","",SUMIFS(J$5:J8,D$5:D8,"Masuk")-SUMIFS(J$5:J8,D$5:D8,"Keluar")) | L8: https://drive.google.com/… (tautan foto nota) | M8: Menunggu Verifikasi | N8: =IF(E8="","",IFERROR(IF(INDEX(Referensi!$B$5:$B$60,MATCH(E8,Referensi!$A$5:$A$60,0))=D8,"OK","Jenis tidak cocok"),"Kategori tidak dikenal"))
A9: =IF(B9="","",ROW()-4) | B9: 46315 | C9: BKK-2610-004 | D9: Keluar | E9: Upah Pekerja Lapangan | F9: =IF(E9="","",IFERROR(INDEX(Referensi!$C$5:$C$60,MATCH(E9,Referensi!$A$5:$A$60,0)),"?")) | G9: Akar Bambu | H9: [CONTOH] Upah 8 pekerja lokal, persiapan lahan 5 hari | I9: Pekerja lokal (8 orang) | J9: 4800000 | K9: =IF(J9="","",SUMIFS(J$5:J9,D$5:D9,"Masuk")-SUMIFS(J$5:J9,D$5:D9,"Keluar")) | L9: https://drive.google.com/… (tautan foto nota) | M9: Terverifikasi | N9: =IF(E9="","",IFERROR(IF(INDEX(Referensi!$B$5:$B$60,MATCH(E9,Referensi!$A$5:$A$60,0))=D9,"OK","Jenis tidak cocok"),"Kategori tidak dikenal"))
A10: =IF(B10="","",ROW()-4) | B10: 46323 | C10: BKM-2610-002 | D10: Masuk | E10: Kemitraan / CSR Perusahaan | F10: =IF(E10="","",IFERROR(INDEX(Referensi!$C$5:$C$60,MATCH(E10,Referensi!$A$5:$A$60,0)),"?")) | G10: Akar Bambu | H10: [CONTOH] Termin 1 kontrak kemitraan penanaman | I10: PT Mitra (nama perusahaan) | J10: 25000000 | K10: =IF(J10="","",SUMIFS(J$5:J10,D$5:D10,"Masuk")-SUMIFS(J$5:J10,D$5:D10,"Keluar")) | L10: https://drive.google.com/… (tautan foto nota) | M10: Terverifikasi | N10: =IF(E10="","",IFERROR(IF(INDEX(Referensi!$B$5:$B$60,MATCH(E10,Referensi!$A$5:$A$60,0))=D10,"OK","Jenis tidak cocok"),"Kategori tidak dikenal"))
A11: =IF(B11="","",ROW()-4) | F11: =IF(E11="","",IFERROR(INDEX(Referensi!$C$5:$C$60,MATCH(E11,Referensi!$A$5:$A$60,0)),"?")) | K11: =IF(J11="","",SUMIFS(J$5:J11,D$5:D11,"Masuk")-SUMIFS(J$5:J11,D$5:D11,"Keluar")) | N11: =IF(E11="","",IFERROR(IF(INDEX(Referensi!$B$5:$B$60,MATCH(E11,Referensi!$A$5:$A$60,0))=D11,"OK","Jenis tidak cocok"),"Kategori tidak dikenal"))
A12: =IF(B12="","",ROW()-4) | F12: =IF(E12="","",IFERROR(INDEX(Referensi!$C$5:$C$60,MATCH(E12,Referensi!$A$5:$A$60,0)),"?")) | K12: =IF(J12="","",SUMIFS(J$5:J12,D$5:D12,"Masuk")-SUMIFS(J$5:J12,D$5:D12,"Keluar")) | N12: =IF(E12="","",IFERROR(IF(INDEX(Referensi!$B$5:$B$60,MATCH(E12,Referensi!$A$5:$A$60,0))=D12,"OK","Jenis tidak cocok"),"Kategori tidak dikenal"))
A13: =IF(B13="","",ROW()-4) | F13: =IF(E13="","",IFERROR(INDEX(Referensi!$C$5:$C$60,MATCH(E13,Referensi!$A$5:$A$60,0)),"?")) | K13: =IF(J13="","",SUMIFS(J$5:J13,D$5:D13,"Masuk")-SUMIFS(J$5:J13,D$5:D13,"Keluar")) | N13: =IF(E13="","",IFERROR(IF(INDEX(Referensi!$B$5:$B$60,MATCH(E13,Referensi!$A$5:$A$60,0))=D13,"OK","Jenis tidak cocok"),"Kategori tidak dikenal"))
A14: =IF(B14="","",ROW()-4) | F14: =IF(E14="","",IFERROR(INDEX(Referensi!$C$5:$C$60,MATCH(E14,Referensi!$A$5:$A$60,0)),"?")) | K14: =IF(J14="","",SUMIFS(J$5:J14,D$5:D14,"Masuk")-SUMIFS(J$5:J14,D$5:D14,"Keluar")) | N14: =IF(E14="","",IFERROR(IF(INDEX(Referensi!$B$5:$B$60,MATCH(E14,Referensi!$A$5:$A$60,0))=D14,"OK","Jenis tidak cocok"),"Kategori tidak dikenal"))
A15: =IF(B15="","",ROW()-4) | F15: =IF(E15="","",IFERROR(INDEX(Referensi!$C$5:$C$60,MATCH(E15,Referensi!$A$5:$A$60,0)),"?")) | K15: =IF(J15="","",SUMIFS(J$5:J15,D$5:D15,"Masuk")-SUMIFS(J$5:J15,D$5:D15,"Keluar")) | N15: =IF(E15="","",IFERROR(IF(INDEX(Referensi!$B$5:$B$60,MATCH(E15,Referensi!$A$5:$A$60,0))=D15,"OK","Jenis tidak cocok"),"Kategori tidak dikenal"))
A16: =IF(B16="","",ROW()-4) | F16: =IF(E16="","",IFERROR(INDEX(Referensi!$C$5:$C$60,MATCH(E16,Referensi!$A$5:$A$60,0)),"?")) | K16: =IF(J16="","",SUMIFS(J$5:J16,D$5:D16,"Masuk")-SUMIFS(J$5:J16,D$5:D16,"Keluar")) | N16: =IF(E16="","",IFERROR(IF(INDEX(Referensi!$B$5:$B$60,MATCH(E16,Referensi!$A$5:$A$60,0))=D16,"OK","Jenis tidak cocok"),"Kategori tidak dikenal"))
A17: =IF(B17="","",ROW()-4) | F17: =IF(E17="","",IFERROR(INDEX(Referensi!$C$5:$C$60,MATCH(E17,Referensi!$A$5:$A$60,0)),"?")) | K17: =IF(J17="","",SUMIFS(J$5:J17,D$5:D17,"Masuk")-SUMIFS(J$5:J17,D$5:D17,"Keluar")) | N17: =IF(E17="","",IFERROR(IF(INDEX(Referensi!$B$5:$B$60,MATCH(E17,Referensi!$A$5:$A$60,0))=D17,"OK","Jenis tidak cocok"),"Kategori tidak dikenal"))
A18: =IF(B18="","",ROW()-4) | F18: =IF(E18="","",IFERROR(INDEX(Referensi!$C$5:$C$60,MATCH(E18,Referensi!$A$5:$A$60,0)),"?")) | K18: =IF(J18="","",SUMIFS(J$5:J18,D$5:D18,"Masuk")-SUMIFS(J$5:J18,D$5:D18,"Keluar")) | N18: =IF(E18="","",IFERROR(IF(INDEX(Referensi!$B$5:$B$60,MATCH(E18,Referensi!$A$5:$A$60,0))=D18,"OK","Jenis tidak cocok"),"Kategori tidak dikenal"))
A19: =IF(B19="","",ROW()-4) | F19: =IF(E19="","",IFERROR(INDEX(Referensi!$C$5:$C$60,MATCH(E19,Referensi!$A$5:$A$60,0)),"?")) | K19: =IF(J19="","",SUMIFS(J$5:J19,D$5:D19,"Masuk")-SUMIFS(J$5:J19,D$5:D19,"Keluar")) | N19: =IF(E19="","",IFERROR(IF(INDEX(Referensi!$B$5:$B$60,MATCH(E19,Referensi!$A$5:$A$60,0))=D19,"OK","Jenis tidak cocok"),"Kategori tidak dikenal"))
A20: =IF(B20="","",ROW()-4) | F20: =IF(E20="","",IFERROR(INDEX(Referensi!$C$5:$C$60,MATCH(E20,Referensi!$A$5:$A$60,0)),"?")) | K20: =IF(J20="","",SUMIFS(J$5:J20,D$5:D20,"Masuk")-SUMIFS(J$5:J20,D$5:D20,"Keluar")) | N20: =IF(E20="","",IFERROR(IF(INDEX(Referensi!$B$5:$B$60,MATCH(E20,Referensi!$A$5:$A$60,0))=D20,"OK","Jenis tidak cocok"),"Kategori tidak dikenal"))
A21: =IF(B21="","",ROW()-4) | F21: =IF(E21="","",IFERROR(INDEX(Referensi!$C$5:$C$60,MATCH(E21,Referensi!$A$5:$A$60,0)),"?")) | K21: =IF(J21="","",SUMIFS(J$5:J21,D$5:D21,"Masuk")-SUMIFS(J$5:J21,D$5:D21,"Keluar")) | N21: =IF(E21="","",IFERROR(IF(INDEX(Referensi!$B$5:$B$60,MATCH(E21,Referensi!$A$5:$A$60,0))=D21,"OK","Jenis tidak cocok"),"Kategori tidak dikenal"))
A22: =IF(B22="","",ROW()-4) | F22: =IF(E22="","",IFERROR(INDEX(Referensi!$C$5:$C$60,MATCH(E22,Referensi!$A$5:$A$60,0)),"?")) | K22: =IF(J22="","",SUMIFS(J$5:J22,D$5:D22,"Masuk")-SUMIFS(J$5:J22,D$5:D22,"Keluar")) | N22: =IF(E22="","",IFERROR(IF(INDEX(Referensi!$B$5:$B$60,MATCH(E22,Referensi!$A$5:$A$60,0))=D22,"OK","Jenis tidak cocok"),"Kategori tidak dikenal"))
... A1004: =IF(B1004="","",ROW()-4) | F1004: =IF(E1004="","",IFERROR(INDEX(Referensi!$C$5:$C$60,MATCH(E1004,Referensi!$A$5:$A$60,0)),"?")) | K1004: =IF(J1004="","",SUMIFS(J$5:J1004,D$5:D1004,"Masuk")-SUMIFS(J$5:J1004,D$5:D1004,"Keluar")) | N1004: =IF(E1004="","",IFERROR(IF(INDEX(Referensi!$B$5:$B$60,MATCH(E1004,Referensi!$A$5:$A$60,0))=D1004,"OK","Jenis tidak cocok"),"Kategori tidak dikenal"))

Sheet Dampak
A1: Buku Kas Publik — Dampak
A2: Satu baris = satu capaian baru (bukan total kumulatif). Isi kolom putih.
A4: No | B4: Tanggal | C4: Proyek | D4: Indikator | E4: Jumlah | F4: Satuan (otomatis) | G4: Lokasi (desa/kecamatan) | H4: Keterangan | I4: Tautan Bukti | J4: Status
A5: =IF(B5="","",ROW()-4) | B5: 46303 | C5: Lapor Lahan & Riset | D5: Laporan lahan diterima | E5: 3 | F5: =IF(D5="","",IFERROR(INDEX(Referensi!$J$5:$J$30,MATCH(D5,Referensi!$I$5:$I$30,0)),"?")) | G5: Kab. contoh | H5: [CONTOH] 3 laporan masuk lewat website | I5: https://drive.google.com/… (tautan foto) | J5: Terverifikasi
A6: =IF(B6="","",ROW()-4) | B6: 46303 | C6: Lapor Lahan & Riset | D6: Lahan disurvei | E6: 1 | F6: =IF(D6="","",IFERROR(INDEX(Referensi!$J$5:$J$30,MATCH(D6,Referensi!$I$5:$I$30,0)),"?")) | G6: Desa contoh | H6: [CONTOH] Survei laporan #001 | I6: https://drive.google.com/… (tautan foto) | J6: Terverifikasi
A7: =IF(B7="","",ROW()-4) | B7: 46315 | C7: Akar Bambu | D7: Pekerja lokal terlibat (baru) | E7: 8 | F7: =IF(D7="","",IFERROR(INDEX(Referensi!$J$5:$J$30,MATCH(D7,Referensi!$I$5:$I$30,0)),"?")) | G7: Desa contoh | H7: [CONTOH] Pekerja persiapan lahan | I7: https://drive.google.com/… (tautan foto) | J7: Terverifikasi
A8: =IF(B8="","",ROW()-4) | B8: 46315 | C8: Akar Bambu | D8: Hari kerja warga | E8: 40 | F8: =IF(D8="","",IFERROR(INDEX(Referensi!$J$5:$J$30,MATCH(D8,Referensi!$I$5:$I$30,0)),"?")) | G8: Desa contoh | H8: [CONTOH] 8 orang × 5 hari | I8: https://drive.google.com/… (tautan foto) | J8: Terverifikasi
A9: =IF(B9="","",ROW()-4) | F9: =IF(D9="","",IFERROR(INDEX(Referensi!$J$5:$J$30,MATCH(D9,Referensi!$I$5:$I$30,0)),"?"))
A10: =IF(B10="","",ROW()-4) | F10: =IF(D10="","",IFERROR(INDEX(Referensi!$J$5:$J$30,MATCH(D10,Referensi!$I$5:$I$30,0)),"?"))
A11: =IF(B11="","",ROW()-4) | F11: =IF(D11="","",IFERROR(INDEX(Referensi!$J$5:$J$30,MATCH(D11,Referensi!$I$5:$I$30,0)),"?"))
A12: =IF(B12="","",ROW()-4) | F12: =IF(D12="","",IFERROR(INDEX(Referensi!$J$5:$J$30,MATCH(D12,Referensi!$I$5:$I$30,0)),"?"))
A13: =IF(B13="","",ROW()-4) | F13: =IF(D13="","",IFERROR(INDEX(Referensi!$J$5:$J$30,MATCH(D13,Referensi!$I$5:$I$30,0)),"?"))
A14: =IF(B14="","",ROW()-4) | F14: =IF(D14="","",IFERROR(INDEX(Referensi!$J$5:$J$30,MATCH(D14,Referensi!$I$5:$I$30,0)),"?"))
A15: =IF(B15="","",ROW()-4) | F15: =IF(D15="","",IFERROR(INDEX(Referensi!$J$5:$J$30,MATCH(D15,Referensi!$I$5:$I$30,0)),"?"))
A16: =IF(B16="","",ROW()-4) | F16: =IF(D16="","",IFERROR(INDEX(Referensi!$J$5:$J$30,MATCH(D16,Referensi!$I$5:$I$30,0)),"?"))
A17: =IF(B17="","",ROW()-4) | F17: =IF(D17="","",IFERROR(INDEX(Referensi!$J$5:$J$30,MATCH(D17,Referensi!$I$5:$I$30,0)),"?"))
A18: =IF(B18="","",ROW()-4) | F18: =IF(D18="","",IFERROR(INDEX(Referensi!$J$5:$J$30,MATCH(D18,Referensi!$I$5:$I$30,0)),"?"))
A19: =IF(B19="","",ROW()-4) | F19: =IF(D19="","",IFERROR(INDEX(Referensi!$J$5:$J$30,MATCH(D19,Referensi!$I$5:$I$30,0)),"?"))
A20: =IF(B20="","",ROW()-4) | F20: =IF(D20="","",IFERROR(INDEX(Referensi!$J$5:$J$30,MATCH(D20,Referensi!$I$5:$I$30,0)),"?"))
... A1004: =IF(B1004="","",ROW()-4) | F1004: =IF(D1004="","",IFERROR(INDEX(Referensi!$J$5:$J$30,MATCH(D1004,Referensi!$I$5:$I$30,0)),"?"))

Sheet Referensi
A1: Daftar Referensi
A2: Isi daftar di bawah untuk pilihan dropdown. Tambahkan baris baru di bawah daftar bila perlu (kolom kuning).
A4: Kategori | B4: Jenis | C4: Kelompok | D4: Keterangan | F4: Proyek | G4: Keterangan | I4: Indikator Dampak | J4: Satuan | L4: Jenis | M4: Status
A5: Modal Disetor Pemegang Saham | B5: Masuk | C5: Pendanaan & Modal | D5: Setoran modal pendiri/pemegang saham PT | F5: Akar Bambu | G5: Agroforestri penyelamatan lahan rawan longsor | I5: Pohon ditanam | J5: batang | L5: Masuk | M5: Terverifikasi
A6: Investasi Dampak | B6: Masuk | C6: Pendanaan & Modal | D6: Dana investor dampak (ekuitas/pinjaman) | F6: Benih | G6: Aplikasi web jejaring penggiat lingkungan | I6: Bibit diproduksi | J6: batang | L6: Keluar | M6: Menunggu Verifikasi
A7: Kemitraan / CSR Perusahaan | B7: Masuk | C7: Pendapatan Usaha | D7: Kontrak program dengan badan usaha | F7: Lapor Lahan & Riset | G7: Verifikasi dan survei laporan lahan kritis | I7: Luas lahan dipulihkan | J7: hektare
A8: Penjualan Hasil Panen | B8: Masuk | C8: Pendapatan Usaha | D8: Bambu, katuk, vanili, dll. | F8: Umum Perusahaan | G8: Biaya/pendapatan yang tidak terkait satu proyek | I8: Pekerja lokal terlibat (baru) | J8: orang
A9: Penjualan Bibit | B9: Masuk | C9: Pendapatan Usaha | D9: Bibit dari persemaian | I9: Hari kerja warga | J9: HOK
A10: Jasa & Program | B10: Masuk | C10: Pendapatan Usaha | D10: Pelatihan, konsultasi, kunjungan lapangan | I10: Laporan lahan diterima | J10: laporan
A11: Pendapatan Lain | B11: Masuk | C11: Pendapatan Usaha | D11: Bunga bank, dll. | I11: Lahan disurvei | J11: lokasi
A12: Bibit & Material Tanam | B12: Keluar | C12: Biaya Proyek | D12: Bibit, pupuk organik, ajir, polybag | I12: Hasil panen | J12: kg
A13: Upah Pekerja Lapangan | B13: Keluar | C13: Biaya Proyek | D13: Tulis per peran/kelompok, bukan nama orang | I13: Penggiat terdaftar di Benih | J13: akun
A14: Honor Ahli & Pendamping | B14: Keluar | C14: Biaya Proyek | D14: Ahli agroforestri, pendamping desa | I14: Kegiatan lingkungan via Benih | J14: kegiatan
A15: Survei & Riset Lahan | B15: Keluar | C15: Biaya Proyek | D15: Survei laporan lahan, uji tanah, pemetaan
A16: Sewa / Kompensasi Lahan | B16: Keluar | C16: Biaya Proyek | D16: Sewa atau bagi hasil dengan pemilik lahan
A17: Transportasi & Logistik | B17: Keluar | C17: Biaya Proyek | D17: Angkut bibit, perjalanan ke lokasi
A18: Peralatan Lapangan | B18: Keluar | C18: Biaya Proyek | D18: Alat tanam, APD
A19: Pengembangan Teknologi | B19: Keluar | C19: Biaya Proyek | D19: Pengembangan aplikasi Benih, server
A20: Gaji Tim Inti | B20: Keluar | C20: Biaya Operasional | D20: Tulis total per bagian, bukan per nama
A21: Operasional Kantor | B21: Keluar | C21: Biaya Operasional | D21: Sewa kantor, listrik, internet, ATK
A22: Pemasaran & Komunikasi | B22: Keluar | C22: Biaya Operasional | D22: Website, media sosial, materi publikasi
A23: Legal, Audit & Administrasi | B23: Keluar | C23: Biaya Operasional | D23: Notaris, perizinan, audit, biaya bank
A24: Pajak | B24: Keluar | C24: Pajak | D24: PPh, PPN, PBB, dll.
A25: Pengeluaran Lain | B25: Keluar | C25: Biaya Operasional | D25: Yang tidak masuk kategori lain
